What will be the output of the below code. Provide necessary information to support your decision.

#include <iostream>
class Printer {
public:
Printer() {}
    ~ Printer() {
        throw 42;
    }
};

int main(int argc, const char * argv[]) {
    try {
Printer hp;
        throw 32;
    } catch(int a) {
        std::cout << a;
    }
}


Explanation:
	     In this program,the base class contain the constructor and destructor block,the throw function occurred in destructor block.
       It is nota valid statement.so it does  not produce any output.

